<?xml version='1.0'?>
<robot name="gopigo3">

  <material name="blue">
    <color rgba="0 0 0.8 1"/>
  </material>

  <material name="white">
    <color rgba="1 1 1 1"/>
  </material>

  <material name="red">
    <color rgba="1 0 0 1"/>
  </material>

  <material name="green">
    <color rgba="0 1 0 1"/>
  </material>

  <material name="yellow">
    <color rgba="1 1 0 1"/>
  </material>

  <material name="orange">
    <color rgba="1 0.54 0 1"/>
  </material>

  <!-- Base Link -->
  <link name="base_link">
    <visual>
      <origin xyz="0 0 0" rpy="0 0 0" />
      <geometry>
          <box size="0.5 0.5 0.25"/>
      </geometry>
      <material name="blue"/>
    </visual>

    <!-- Base collision, mass and inertia -->
    <collision>
      <origin xyz="0 0 0" rpy="0 0 0" />
      <geometry>
          <box size="0.5 0.5 0.25"/>
      </geometry>
    </collision>

    <inertial>
      <origin xyz="0 0 0" rpy="0 0 0" />
      <mass value="5"/>
      <inertia ixx="0.13" ixy="0.0" ixz="0.0" iyy="0.21" iyz="0.0" izz="0.13"/>
    </inertial>

    <!-- Caster attachment -->
    <visual name="caster_visual">
      <origin xyz="-0.2 0 -0.125" rpy="0 0 0" />
      <geometry>
        <sphere radius="0.075" />
      </geometry>
    </visual>

    <collision name="caster_collision">
      <origin xyz="-0.2 0 -0.125" rpy="0 0 0" />
      <geometry>
        <sphere radius="0.075" />
      </geometry>
    </collision>

    <inertial name="caster_inertia">
      <origin xyz="-0.2 0 -0.125" rpy="0 0 0" />
      <mass value="0.5"/>
      <inertia ixx="0.0001" ixy="0.0" ixz="0.0" iyy="0.0001" iyz="0.0" izz="0.0001"/>
    </inertial>

  </link>
 
  <!-- Right Wheel -->
  <link name="right_wheel">
    <visual>
      <origin xyz="0 0 0" rpy="1.570795 0 0" />
      <geometry>
          <cylinder length="0.1" radius="0.2" />
      </geometry>
      <material name="orange"/>
    </visual>
    <!-- Right Wheel collision, mass and inertia -->
    <collision>
      <origin xyz="0 0 0" rpy="1.570795 0 0" />
      <geometry>
          <cylinder length="0.1" radius="0.2" />
      </geometry>
    </collision>
    <inertial>
      <origin xyz="0 0 0" rpy="1.570795 0 0" />
      <mass value="0.5"/>
      <inertia ixx="0.01" ixy="0.0" ixz="0.0" iyy="0.005" iyz="0.0" izz="0.005"/>
    </inertial>

  </link>

  <!-- Right Wheel joint -->
  <joint name="joint_right_wheel" type="continuous">
    <parent link="base_link"/>
    <child link="right_wheel"/>
    <origin xyz="0.2 -0.30 0.025" rpy="0 0 0" /> 
    <axis xyz="0 1 0" />
  </joint>
  <!-- Left Wheel joint -->
  <joint name="joint_left_wheel" type="continuous">
    <parent link="base_link"/>
    <child link="left_wheel"/>
    <origin xyz="0.2 0.30 0.025" rpy="0 0 0" /> 
    <axis xyz="0 1 0"/>
  </joint>

  <!-- Left Wheel -->
  <link name="left_wheel">
    <visual>
      <origin xyz="0 0 0" rpy="1.570795 0 0" />
      <geometry>
          <cylinder length="0.1" radius="0.2" />
      </geometry>
      <material name="orange"/>
    </visual>
    <!-- Left Wheel collision, mass and inertia -->
    <collision>
      <origin xyz="0 0 0" rpy="1.570795 0 0" />
      <geometry>
          <cylinder length="0.1" radius="0.2" />
      </geometry>
    </collision>
    <inertial>
      <origin xyz="0 0 0" rpy="1.570795 0 0" />
      <mass value="0.5"/>
      <inertia ixx="0.01" ixy="0.0" ixz="0.0" iyy="0.005" iyz="0.0" izz="0.005"/>
    </inertial>

  </link>

<!-- Distance Sensor -->
  <joint name="distance_sensor_joint" type="fixed">
    <axis xyz="0 1 0" />
    <origin rpy="0 0 0" xyz="0.245 0 0.13" />
    <parent link="base_link"/>
    <child link="distance_sensor"/>
  </joint>

  <link name="distance_sensor">
    <visual>
      <origin xyz="0 0 0" rpy="0 0 0"/>
      <geometry>
        <box size="0.01 0.01 0.01"/>
      </geometry>
      <material name="red"/>
    </visual>
  </link>
  
  <!-- Distance Sensor solid-->
  <joint name="distance_sensor_solid_joint" type="fixed">
    <axis xyz="0 1 0" />
    <origin rpy="0 0 0" xyz="0 0 0" />
    <parent link="base_link"/>
    <child link="distance_sensor_solid"/>
  </joint>

  <link name="distance_sensor_solid">
    <collision>
      <origin xyz="0.2 0 0.155" rpy="1.570795 0 1.570795" />
      <geometry>
        <box size="0.01 0.01 0.01"/>
      </geometry>
    </collision>

    <visual>
      <origin xyz="0.2 0 0.155" rpy="1.570795 0 1.570795" />
      <geometry>
        <mesh filename="package://gopigo3_description/meshes/IR_Sensor_Sharp_GP2Y_solid.stl" scale="0.005 0.005 0.005"/>
      </geometry>
      <material name="red"/>
    </visual>

    <inertial>
      <origin xyz="0.2 0 0.155" rpy="1.570795 0 1.570795" />
      <mass value="1e-5" />
      <origin xyz="0 0 0" rpy="0 0 0"/>
      <inertia ixx="1e-6" ixy="0" ixz="0" iyy="1e-6" iyz="0" izz="1e-6" />
    </inertial>
  </link>

  <!-- 2D Camera as a mesh of actual PiCamera -->
  <link name="camera">
    <visual>
      <origin xyz="0.25 0 0.05" rpy="0 1.570795 0" />
      <geometry>
        <mesh filename="package://gopigo3_description/meshes/piCamera.stl" scale="0.005 0.005 0.005"/>
      </geometry>
      <material name="yellow"/>
    </visual>
    
    <collision>
      <origin xyz="0.275 0 0.05" rpy="0 -1.570795 0" />
      <geometry>
        <box size="0.15 0.15 0.05"/>
      </geometry>
    </collision>

    <inertial>
      <origin xyz="0.275 0 0.05" rpy="0 -1.570795 0" />
      <mass value="1e-3" />
      <inertia ixx="1e-6" ixy="0" ixz="0" iyy="1e-6" iyz="0" izz="1e-6" />
    </inertial>
  </link>

  <joint name="joint_camera" type="fixed">
    <axis xyz="0 0 1" />
    <origin xyz="0 0 0" rpy="0 0 0"/>
    <parent link="base_link"/>
    <child link="camera"/>
  </joint>

  <!-- GAZEBO MATERIAL TAGS (colors for sensors under <sensor> tags) -->
  <gazebo reference="base_link">
    <material>Gazebo/Blue</material>
    <pose>0 0 3 0 0 0</pose>
  </gazebo>

  <gazebo reference="right_wheel">
    <material>Gazebo/White</material>
  </gazebo>

  <gazebo reference="left_wheel">
    <material>Gazebo/White</material>
  </gazebo>

  <!-- SENSOR AND ACTUATORS (only Gazebo, not part of URDF) -->
  <!-- Differential Drive Controller -->
  <!-- https://answers.ros.org/question/236122/diffdrive-odometry-source-is-missing -->
  <gazebo>
    <plugin filename="libgazebo_ros_diff_drive.so" name="differential_drive_controller">
      <alwaysOn>true</alwaysOn>
      <updateRate>20</updateRate>
      <leftJoint>joint_left_wheel</leftJoint>
      <rightJoint>joint_right_wheel</rightJoint>
      <wheelSeparation>0.6</wheelSeparation>
      <wheelDiameter>0.3</wheelDiameter>
      <torque>0.1</torque>
      <commandTopic>cmd_vel</commandTopic>
      <odometryTopic>odom</odometryTopic>
      <odometryFrame>odom</odometryFrame>
      <robotBaseFrame>base_link</robotBaseFrame>
      <legacyMode>false</legacyMode>
      <publishTf>1</publishTf>
      <rosDebugLevel>na</rosDebugLevel>
      <publishWheelTF>false</publishWheelTF>
      <publishOdomTF>true</publishOdomTF>
      <publishWheelJointState>false</publishWheelJointState>
      <wheelAcceleration>0</wheelAcceleration>
      <wheelTorque>5</wheelTorque>
    </plugin>
  </gazebo>

<!-- Distance Sensor controller -->
<gazebo reference="distance_sensor">        
   <sensor type="ray" name="laser_distance">
      <material>Gazebo/White</material>
      <pose>0 0 0 0 0 0</pose>
      <visualize>true</visualize>
      <update_rate>10</update_rate>
      <ray>
         <scan>
            <horizontal>
               <samples>10</samples>
               <resolution>1</resolution> 
               <min_angle>-0.01</min_angle>
               <max_angle>0.01</max_angle>
            </horizontal>
            <vertical>
               <samples>10</samples>
               <resolution>1</resolution> 
               <min_angle>-0.01</min_angle>
               <max_angle>0.01</max_angle> 
            </vertical>
         </scan>
         <range>
            <min>0.01</min>
            <max>3</max>
            <resolution>0.01</resolution>
         </range>
      </ray>
      <plugin filename="libgazebo_ros_range.so" name="gazebo_ros_ir">
         <gaussianNoise>0.005</gaussianNoise>
         <alwaysOn>true</alwaysOn>
         <updateRate>0.0</updateRate>
         <topicName>gopigo/distance</topicName>
         <frameName>distance_sensor</frameName>
         <radiation>INFRARED</radiation>
         <fov>0.02</fov>
      </plugin>
    </sensor>  
   </gazebo>

<!-- 2D Camera controller -->
<gazebo reference="camera">
    <sensor type="camera" name="camera1">
      <update_rate>30.0</update_rate>
      <camera name="front">
        <horizontal_fov>1.3962634</horizontal_fov>
        <image>
          <width>800</width>
          <height>800</height>
          <format>R8G8B8</format>
        </image>
        <clip>
          <near>0.02</near>
          <far>300</far>
        </clip>
      </camera>
      <plugin name="camera_controller" filename="libgazebo_ros_camera.so">
        <alwaysOn>true</alwaysOn>
        <updateRate>0.0</updateRate>
        <cameraName>gopigo/camera1</cameraName>
        <imageTopicName>image_raw</imageTopicName>
        <cameraInfoTopicName>camera_info</cameraInfoTopicName>
        <frameName>camera</frameName>
        <hackBaseline>0.07</hackBaseline>
        <distortionK1>0.0</distortionK1>
        <distortionK2>0.0</distortionK2>
        <distortionK3>0.0</distortionK3>
        <distortionT1>0.0</distortionT1>
        <distortionT2>0.0</distortionT2>
      </plugin>
    </sensor>
  </gazebo>

</robot>
