<?xml version='1.0'?>

<robot name="Rover" xmlns:xacro="http://www.ros.org/wiki/xacro">

  <xacro:include filename="$(find rover_description)/urdf/rover.gazebo" />
  <xacro:include filename="$(find rover_description)/urdf/materials.xacro"/>
  
  
  <link name='base_footprint'>
    <pose>0 0 0 0 0 0</pose>

    <inertial>
      <mass value="5"/>
      <inertia ixx="0.13" ixy="0.0" ixz="0.0" iyy="0.21" iyz="0.0" izz="0.13"/>
    </inertial>

    <collision name='collision'>
      <origin xyz="0 0 0" rpy="0 0 0" />
      <geometry>
          <box size="0.5 0.5 0.25"/>
      </geometry>
    </collision>

    <visual name='base_footprint_visual'>
      <origin xyz="0 0 0" rpy="0 0 0" />
      <geometry>
          <box size="0.5 0.5 0.25"/>
      </geometry>
    </visual>
  </link>

  <link name="left_wheel_front">
    <visual>
      <origin xyz="0 0 0" rpy="1.570795 0 0" />
      <geometry>
          <cylinder length="0.1" radius="0.2" />
      </geometry>
    </visual>
    <!-- Left Wheel collision, mass and inertia -->
    <collision>
      <origin xyz="0 0 0" rpy="1.570795 0 0" />
      <geometry>
          <cylinder length="0.1" radius="0.2" />
      </geometry>
    </collision>
    <inertial>
      <mass value="0.5"/>
      <inertia ixx="0.01" ixy="0.0" ixz="0.0" iyy="0.005" iyz="0.0" izz="0.005"/>
    </inertial>
  </link>

  <link name="right_wheel_front">
    <visual>
      <origin xyz="0 0 0" rpy="1.570795 0 0" />
      <geometry>
          <cylinder length="0.1" radius="0.2" />
      </geometry>
    </visual>
    <!-- Right Wheel collision, mass and inertia -->
    <collision>
      <origin xyz="0 0 0" rpy="1.570795 0 0" />
      <geometry>
          <cylinder length="0.1" radius="0.2" />
      </geometry>
    </collision>
    <inertial>
      <mass value="0.5"/>
      <inertia ixx="0.01" ixy="0.0" ixz="0.0" iyy="0.005" iyz="0.0" izz="0.005"/>
    </inertial>
  </link>

  <link name="caster_wheel">
    <collision name="collision">
      <origin xyz="0 0 0" rpy="1.570795 0 0"/>
      <geometry>
        <sphere radius="0.05"/>
      </geometry>
    </collision>

    <visual name="right_wheel_visual">
      <origin xyz="0 0 0" rpy="1.570795 0 0"/>
      <geometry>
        <sphere radius="0.05"/>
      </geometry>
    </visual>

    <inertial>
      <origin xyz="0 0 0" rpy="1.570795 0 0"/>
      <mass value="0.5"/>
      <inertia
        ixx=".1" ixy="0.0" ixz="0.0"
        iyy=".1" iyz="0.0"
        izz=".1"/>
    </inertial>
  </link>

  
  <joint type="continuous" name="left_wheel_front_hinge">
    <origin xyz="0 0.30 0.025" rpy="0 0 0" /> 
    <child link="left_wheel_front"/>
    <parent link="base_footprint"/>
    <axis xyz="0 1 0" rpy="0 0 0"/>
    <limit effort="10000" velocity="1000"/>
    <joint_properties damping="1.0" friction="1.0"/>
  </joint>

  <joint type="continuous" name="right_wheel_front_hinge">
    <origin xyz="0 -0.30 0.025" rpy="0 0 0" /> 
    <child link="right_wheel_front"/>
    <parent link="base_footprint"/>
    <axis xyz="0 1 0" rpy="0 0 0"/>
    <limit effort="10000" velocity="1000"/>
    <joint_properties damping="1.0" friction="1.0"/>
  </joint>

  <joint type="continuous" name="caster_wheel_hinge">
    <origin xyz="-0.2 0 -0.125" rpy="0 0 0" />
    <child link="caster_wheel"/>
    <parent link="base_footprint"/>
    <axis xyz="0 1 0" rpy="0 0 0"/>
    <limit effort="10000" velocity="1000"/>
    <joint_properties damping="1.0" friction="1.0"/>
  </joint>

  <!-- DISTANCE SENSOR -->
  <!-- Infrared sensor assembly -->
  <joint name="ir_front_joint" type="fixed">
    <axis xyz="0 1 0" />
    <origin rpy="0 0 0" xyz="0.245 0 0.13" />
    <parent link="base_footprint"/>
    <child link="base_ir_front"/>
  </joint>
  
  <link name="base_ir_front">
    <collision>
      <origin xyz="0 0 0" rpy="0 0 0"/>
      <geometry>
        <box size="0.01 0.01 0.01"/>
      </geometry>
    </collision>
    <visual>
      <origin xyz="0 0 0" rpy="0 0 0"/>
      <geometry>
        <box size="0.01 0.01 0.01"/>
      </geometry>
    </visual>
    <inertial>
      <mass value="1e-5" />
      <origin xyz="0 0 0" rpy="0 0 0"/>
      <inertia ixx="1e-6" ixy="0" ixz="0" iyy="1e-6" iyz="0"      izz="1e-6" />
    </inertial>
  </link>

</robot>